// 错误传递
// 错误会一直沿着函数调用链向上抛出
// 在一个合适的地方统一捕获错误
function main(s) {
    console.log('BEGIN main()');
    try {
        foo(s);
    } catch (e) {
        console.log('出错了：' + e);
    }
    console.log('END main()');
}

function foo(s) {
    console.log('BEGIN foo()');
    bar(s);
    console.log('END foo()');
}

function bar(s) {
    console.log('BEGIN bar()');
    console.log('length = ' + s.length);
    console.log('END bar()');
}

main(null);
